Workbook

Sheet Summary
A1: Pharmacy Chain ERP — Full API Test Plan
A2: One sheet per module. Fill in 'Actual Result', set 'Status', 'Tested By' and 'Date Tested' on each tab as you go — the counts below update automatically.
A4: Module / Tab | B4: Total Test Cases | C4: Pass | D4: Fail | E4: Blocked | F4: Not Tested | G4: % Complete
A5: Auth | B5: =COUNTA(Auth!$A$5:$A$25) -> 21 | C5: =COUNTIF(Auth!$L$5:$L$25,"Pass") -> 21 | D5: =COUNTIF(Auth!$L$5:$L$25,"Fail") -> 0 | E5: =COUNTIF(Auth!$L$5:$L$25,"Blocked") -> 0 | F5: =COUNTIF(Auth!$L$5:$L$25,"Not Tested") -> 0 | G5: =IFERROR((C5+D5+E5)/B5,0) -> 1
A6: Branches | B6: =COUNTA(Branches!$A$5:$A$12) -> 8 | C6: =COUNTIF(Branches!$L$5:$L$12,"Pass") -> 8 | D6: =COUNTIF(Branches!$L$5:$L$12,"Fail") -> 0 | E6: =COUNTIF(Branches!$L$5:$L$12,"Blocked") -> 0 | F6: =COUNTIF(Branches!$L$5:$L$12,"Not Tested") -> 0 | G6: =IFERROR((C6+D6+E6)/B6,0) -> 1
A7: Inventory | B7: =COUNTA(Inventory!$A$5:$A$23) -> 19 | C7: =COUNTIF(Inventory!$L$5:$L$23,"Pass") -> 19 | D7: =COUNTIF(Inventory!$L$5:$L$23,"Fail") -> 0 | E7: =COUNTIF(Inventory!$L$5:$L$23,"Blocked") -> 0 | F7: =COUNTIF(Inventory!$L$5:$L$23,"Not Tested") -> 0 | G7: =IFERROR((C7+D7+E7)/B7,0) -> 1
A8: Suppliers | B8: =COUNTA(Suppliers!$A$5:$A$18) -> 14 | C8: =COUNTIF(Suppliers!$L$5:$L$18,"Pass") -> 12 | D8: =COUNTIF(Suppliers!$L$5:$L$18,"Fail") -> 2 | E8: =COUNTIF(Suppliers!$L$5:$L$18,"Blocked") -> 0 | F8: =COUNTIF(Suppliers!$L$5:$L$18,"Not Tested") -> 0 | G8: =IFERROR((C8+D8+E8)/B8,0) -> 1
A9: Sales-POS | B9: =COUNTA('Sales-POS'!$A$5:$A$19) -> 15 | C9: =COUNTIF('Sales-POS'!$L$5:$L$19,"Pass") -> 13 | D9: =COUNTIF('Sales-POS'!$L$5:$L$19,"Fail") -> 2 | E9: =COUNTIF('Sales-POS'!$L$5:$L$19,"Blocked") -> 0 | F9: =COUNTIF('Sales-POS'!$L$5:$L$19,"Not Tested") -> 0 | G9: =IFERROR((C9+D9+E9)/B9,0) -> 1
A10: Finance | B10: =COUNTA(Finance!$A$5:$A$16) -> 12 | C10: =COUNTIF(Finance!$L$5:$L$16,"Pass") -> 9 | D10: =COUNTIF(Finance!$L$5:$L$16,"Fail") -> 3 | E10: =COUNTIF(Finance!$L$5:$L$16,"Blocked") -> 0 | F10: =COUNTIF(Finance!$L$5:$L$16,"Not Tested") -> 0 | G10: =IFERROR((C10+D10+E10)/B10,0) -> 1
A11: CRM | B11: =COUNTA(CRM!$A$5:$A$11) -> 7 | C11: =COUNTIF(CRM!$L$5:$L$11,"Pass") -> 7 | D11: =COUNTIF(CRM!$L$5:$L$11,"Fail") -> 0 | E11: =COUNTIF(CRM!$L$5:$L$11,"Blocked") -> 0 | F11: =COUNTIF(CRM!$L$5:$L$11,"Not Tested") -> 0 | G11: =IFERROR((C11+D11+E11)/B11,0) -> 1
A12: Analytics | B12: =COUNTA(Analytics!$A$5:$A$24) -> 20 | C12: =COUNTIF(Analytics!$L$5:$L$24,"Pass") -> 19 | D12: =COUNTIF(Analytics!$L$5:$L$24,"Fail") -> 1 | E12: =COUNTIF(Analytics!$L$5:$L$24,"Blocked") -> 0 | F12: =COUNTIF(Analytics!$L$5:$L$24,"Not Tested") -> 0 | G12: =IFERROR((C12+D12+E12)/B12,0) -> 1
A13: RBAC | B13: =COUNTA(RBAC!$A$5:$A$15) -> 11 | C13: =COUNTIF(RBAC!$L$5:$L$15,"Pass") -> 11 | D13: =COUNTIF(RBAC!$L$5:$L$15,"Fail") -> 0 | E13: =COUNTIF(RBAC!$L$5:$L$15,"Blocked") -> 0 | F13: =COUNTIF(RBAC!$L$5:$L$15,"Not Tested") -> 0 | G13: =IFERROR((C13+D13+E13)/B13,0) -> 1
A14: TOTAL | B14: =SUM(B5:B13) -> 127 | C14: =SUM(C5:C13) -> 119 | D14: =SUM(D5:D13) -> 8 | E14: =SUM(E5:E13) -> 0 | F14: =SUM(F5:F13) -> 0 | G14: =IFERROR((C14+D14+E14)/B14,0) -> 1
A17: Legend / Notes:
A18: • 'Not Tested' is the default Status on every row — change it via the dropdown in column L of each module sheet as you test.
A19: • Replace placeholders like {id}, <medicine_id>, <refresh_token> etc. in Sample Request Body with real values from your own test data.
A20: • Seeded demo accounts (run 'python manage.py seed_demo_data'): owner / Owner@12345, manager1 / Manager@12345, cashier1 / Cashier@12345, accountant1 / Accountant@12345, pharmacist1 / Pharmacist@12345.
A21: • All Analytics endpoints depend on the Postgres stored procedures in /sql — run those first if you see 500 errors there.
A22: • RBAC sheet cases should be repeated against EVERY role listed, not just one — log each role's result separately in 'Notes' if the Status column only fits one outcome.

Sheet Auth
A1: Pharmacy Chain ERP — API Test Plan: Auth
A2: Login, JWT tokens, staff/user management. Test with the 5 seeded demo accounts (owner / manager1 / cashier1 / accountant1 / pharmacist1).
A4: Test ID | B4: Module | C4: Endpoint | D4: Method | E4: Test Scenario | F4: Role / User | G4: Preconditions | H4: Sample Request Body | I4: Expected Status | J4: Expected Result | K4: Actual Result | L4: Status | M4: Bug / Notes | N4: Tested By | O4: Date Tested
A5: AUTH-01 | B5: Auth | C5: /api/auth/login/ | D5: POST | E5: Login with valid Owner credentials | F5: Owner | G5: Seed data run (seed_demo_data) | H5: {"username":"owner","password":"Owner@12345"} | I5: 200 | J5: Returns access, refresh tokens + user object with role=OWNER, branch=null | K5: { "refresh": "eyJhbGciOiJIUzI1NiIsInR5cCI6IkpXVCJ9.eyJ0b2tlbl90eXBlIjoicmVmcmVzaCIsImV4cCI6MTc4OTcyNDcwNCwiaWF0IjoxNzg5MTE5OTA0LCJqdGkiOiI3ZDk4YmZjZTRiNmE0MWY4OTI2ZGExMmM5YmY4MzM1MCIsInVzZXJfaWQiOjEsInJvbGUiOiJPV05FUiIsImJyYW5jaF9pZCI6bnVsbCwiZnVsbF9uYW1lIjoiQWxpIE93bmVyIn0.TSgJG254S6RC8q-RHrLnKIrhLzCxC3utTyOpOLvwl08", "access": "eyJhbGciOiJIUzI1NiIsInR5cCI6IkpXVCJ9.eyJ0b2tlbl90eXBlIjoiYWNjZXNzIiwiZXhwIjoxNzg5MTIzNTA0LCJpYXQiOjE3ODkxMTk5MDQsImp0aSI6IjRjMTE4YTAzNzFmMDQwMGNhNWI0YTVjOGU0MzNkN2YwIiwidXNlcl9pZCI6MSwicm9sZSI6Ik9XTkVSIiwiYnJhbmNoX2lkIjpudWxsLCJmdWxsX25hbWUiOiJBbGkgT3duZXIifQ.pZmGBsp_MOZ0t2rH685rWL_WO9CzsjxXTT1Lyxt3tfk", "user": { "id": 1, "username": "owner", "email": "", "first_name": "Ali", "last_name": "Owner", "role": "OWNER", "branch": null, "branch_name": null, "phone": "", "cnic": "", "is_active_staff": true, "date_joined": "2026-09-05T12:57:25.026385+05:00" } } | L5: Pass | N5: Abdullah | O5: 11th September 2026
A6: AUTH-02 | B6: Auth | C6: /api/auth/login/ | D6: POST | E6: Login with valid Cashier credentials | F6: Cashier | G6: Seed data run | H6: {"username":"cashier1","password":"Cashier@12345"} | I6: 200 | J6: Returns tokens + user object with role=CASHIER, branch=1 | K6: { "refresh": "eyJhbGciOiJIUzI1NiIsInR5cCI6IkpXVCJ9.eyJ0b2tlbl90eXBlIjoicmVmcmVzaCIsImV4cCI6MTc4OTcyNDg3NSwiaWF0IjoxNzg5MTIwMDc1LCJqdGkiOiI4ZjIxMmJjOGExYjA0NTAwYjZhNmIwNWVmNzRjNGE3MiIsInVzZXJfaWQiOjMsInJvbGUiOiJDQVNISUVSIiwiYnJhbmNoX2lkIjoxLCJmdWxsX25hbWUiOiJCaWxhbCBDYXNoaWVyIn0.EfzNS91Nf3uHLXbFgCbiTFWmIn3XB8swgoUB2NcxYKk", "access": "eyJhbGciOiJIUzI1NiIsInR5cCI6IkpXVCJ9.eyJ0b2tlbl90eXBlIjoiYWNjZXNzIiwiZXhwIjoxNzg5MTIzNjc1LCJpYXQiOjE3ODkxMjAwNzUsImp0aSI6IjA3ZDk0MmJlNWRkMzRjNzdhZjI0MzU0MWE2ZDM3ODQxIiwidXNlcl9pZCI6Mywicm9sZSI6IkNBU0hJRVIiLCJicmFuY2hfaWQiOjEsImZ1bGxfbmFtZSI6IkJpbGFsIENhc2hpZXIifQ.kPwQ1W2sJA_UpLj4rTud_p5wGBD_tMV1FYcAGFR0uvE", "user": { "id": 3, "username": "cashier1", "email": "", "first_name": "Bilal", "last_name": "Cashier", "role": "CASHIER", "branch": 1, "branch_name": "Main Pharmacy", "phone": "", "cnic": "", "is_active_staff": true, "date_joined": "2026-09-05T12:57:28.125214+05:00" } } | L6: Pass | N6: Abdullah | O6: 12th September 2026
A7: AUTH-03 | B7: Auth | C7: /api/auth/login/ | D7: POST | E7: Login with wrong password | F7: Any | G7: None | H7: {"username":"owner","password":"WrongPass123"} | I7: 401 | J7: Returns 'No active account found with the given credentials' | K7: { "success": false, "errors": { "detail": "No active account found with the given credentials" }, "status_code": 401 } | L7: Pass | N7: Abdullah | O7: 13th September 2026
A8: AUTH-04 | B8: Auth | C8: /api/auth/login/ | D8: POST | E8: Login with non-existent username | F8: Any | G8: None | H8: {"username":"doesnotexist","password":"x"} | I8: 401 | J8: Same generic invalid-credentials error (no user enumeration) | K8: { "success": false, "errors": { "detail": "No active account found with the given credentials" }, "status_code": 401 } | L8: Pass | N8: Abdullah | O8: 14th September 2026
A9: AUTH-05 | B9: Auth | C9: /api/auth/login/ | D9: POST | E9: Login with missing password field | F9: Any | G9: None | H9: {"username":"owner"} | I9: 400 | J9: Validation error: password field required | K9: { "success": false, "errors": { "password": [ "This field is required." ] }, "status_code": 400 } | L9: Pass | N9: Abdullah | O9: 15th September 2026
A10: AUTH-06 | B10: Auth | C10: /api/auth/me/ | D10: GET | E10: Fetch own profile with valid access token | F10: Any logged-in role | G10: Valid access token in Authorization header | H10: (no body — Bearer token only) | I10: 200 | J10: Returns id, username, role, branch, branch_name, phone, etc. | K10: { "id": 1, "username": "owner", "email": "", "first_name": "Ali", "last_name": "Owner", "role": "OWNER", "branch": null, "branch_name": null, "phone": "", "cnic": "", "is_active_staff": true, "date_joined": "2026-09-05T12:57:25.026385+05:00" } | L10: Pass | N10: Abdullah | O10: 16th September 2026
A11: AUTH-07 | B11: Auth | C11: /api/auth/me/ | D11: GET | E11: Fetch profile with no token | F11: N/A | G11: Remove Authorization header | H11: (no auth header) | I11: 401 | J11: 'Authentication credentials were not provided.' | L11: Pass | N11: Abdullah | O11: 17th September 2026
A12: AUTH-08 | B12: Auth | C12: /api/auth/me/ | D12: GET | E12: Fetch profile with expired/invalid token | F12: N/A | G12: Use a garbage/expired JWT | H12: Authorization: Bearer invalidtoken123 | I12: 401 | J12: Token error message | L12: Pass | N12: Abdullah | O12: 18th September 2026
A13: AUTH-09 | B13: Auth | C13: /api/auth/token/refresh/ | D13: POST | E13: Refresh access token using valid refresh token | F13: Any | G13: Have a valid refresh token from login | H13: {"refresh":"<refresh_token>"} | I13: 200 | J13: Returns a new access token (and rotated refresh token, old one blacklisted) | K13: { "access": "eyJhbGciOiJIUzI1NiIsInR5cCI6IkpXVCJ9.eyJ0b2tlbl90eXBlIjoiYWNjZXNzIiwiZXhwIjoxNzg5MTI0MDI5LCJpYXQiOjE3ODkxMjAyNjIsImp0aSI6IjQzYjhmNWEyYTM2YzQ4NmFhMzBmZmE1ODU0MDRlNDdiIiwidXNlcl9pZCI6MSwicm9sZSI6Ik9XTkVSIiwiYnJhbmNoX2lkIjpudWxsLCJmdWxsX25hbWUiOiJBbGkgT3duZXIifQ.eJYcJRaMFQ4923l4P63wk39ijhdCHgUBPtC2z69JU2Y", "refresh": "eyJhbGciOiJIUzI1NiIsInR5cCI6IkpXVCJ9.eyJ0b2tlbl90eXBlIjoicmVmcmVzaCIsImV4cCI6MTc4OTcyNTIyOSwiaWF0IjoxNzg5MTIwNDI5LCJqdGkiOiI5YjFkOGMzZTYyNzU0MTM0YTI2MjUyZmIyMmRiYzY2ZCIsInVzZXJfaWQiOjEsInJvbGUiOiJPV05FUiIsImJyYW5jaF9pZCI6bnVsbCwiZnVsbF9uYW1lIjoiQWxpIE93bmVyIn0.Oq_9QhB3bXatFWJ12pKvuwiHFTIqqf4oguIeEk3R1Po" } | L13: Pass | N13: Abdullah | O13: 19th September 2026
A14: AUTH-10 | B14: Auth | C14: /api/auth/token/refresh/ | D14: POST | E14: Reuse an already-rotated (blacklisted) refresh token | F14: Any | G14: Use the OLD refresh token after AUTH-09 already rotated it | H14: {"refresh":"<old_refresh_token>"} | I14: 401 | J14: Token blacklisted / invalid error | L14: Pass | N14: Abdullah | O14: 20th September 2026
A15: AUTH-11 | B15: Auth | C15: /api/auth/change-password/ | D15: POST | E15: Change own password with correct old password | F15: Any logged-in role | G15: Know current password | H15: {"old_password":"Cashier@12345","new_password":"NewPass@2026"} | I15: 200 | J15: 'Password updated successfully.' — can log in with new password afterward | K15: { "detail": "Password updated successfully." } | L15: Pass | N15: Abdullah | O15: 21st September 2026
A16: AUTH-12 | B16: Auth | C16: /api/auth/change-password/ | D16: POST | E16: Change password with wrong old password | F16: Any | G16: None | H16: {"old_password":"WrongOld","new_password":"NewPass@2026"} | I16: 400 | J16: 'Old password is incorrect.' | K16: { "detail": "Old password is incorrect." } | L16: Pass | N16: Abdullah | O16: 22nd September 2026
A17: AUTH-13 | B17: Auth | C17: /api/auth/change-password/ | D17: POST | E17: Change password to a weak/common password | F17: Any | G17: None | H17: {"old_password":"Cashier@12345","new_password":"12345"} | I17: 400 | J17: Django password validators reject it (too short/common/numeric) | K17: { "success": false, "errors": { "new_password": [ "This password is too short. It must contain at least 8 characters.", "This password is too common.", "This password is entirely numeric." ] }, "status_code": 400 } | L17: Pass | N17: Abdullah | O17: 23rd September 2026
A18: AUTH-14 | B18: Auth | C18: /api/auth/staff/ | D18: GET | E18: Owner lists all staff across all branches | F18: Owner | G18: Multiple staff exist across branches | H18: (no body) | I18: 200 | J18: Returns staff list from ALL branches, excluding OWNER role accounts | K18: { "count": 5, "next": null, "previous": null, "results": [ { "id": 3, "username": "cashier1", "email": "", "first_name": "Bilal", "last_name": "Cashier", "role": "CASHIER", "branch": 1, "branch_name": "Main Pharmacy", "phone": "", "cnic": "", "is_active_staff": true, "date_joined": "2026-09-05T12:57:28.125214+05:00" }, { "id": 4, "username": "accountant1", "email": "", "first_name": "Ayesha", "last_name": "Accountant", "role": "ACCOUNTANT", "branch": 1, "branch_name": "Main Pharmacy", "phone": "", "cnic": "", "is_active_staff": true, "date_joined": "2026-09-05T12:57:29.905323+05:00" }, { "id": 5, "username": "pharmacist1", "email": "", "first_name": "Usman", "last_name": "Pharmacist", "role": "PHARMACIST", "branch": 1, "branch_name": "Main Pharmacy", "phone": "", "cnic": "", "is_active_staff": true, "date_joined": "2026-09-05T12:57:31.408540+05:00" }, { "id": 6, "username": "testcashier", "email": "testcashier@example.com", "first_name": "Test", "last_name": "Cashier", "role": "CASHIER", "branch": 1, "branch_name": "Main Pharmacy", "phone": "03001234567", "cnic": "00000-0000000-0", "is_active_staff": true, "date_joined": "2026-09-05T13:25:59.489448+05:00" }, { "id": 2, "username": "manager1", "email": "", "first_name": "Sara", "last_name": "Manager", "role": "MANAGER", "branch": 1, "branch_name": "Main Pharmacy", "phone": "03009999999", "cnic": "", "is_active_staff": true, "date_joined": "2026-09-05T12:57:26.633080+05:00" } ] } | L18: Pass | N18: Abdullah | O18: 24th September 2026
A19: AUTH-15 | B19: Auth | C19: /api/auth/staff/ | D19: GET | E19: Manager lists staff — should see own branch only | F19: Manager | G19: Staff exist in multiple branches | H19: (no body) | I19: 200 | J19: Only staff whose branch == manager's own branch are returned | K19: { "count": 3, "next": null, "previous": null, "results": [ { "id": 3, "username": "cashier1", "email": "", "first_name": "Bilal", "last_name": "Cashier", "role": "CASHIER", "branch": 1, "branch_name": "Main Pharmacy", "phone": "", "cnic": "", "is_active_staff": true, "date_joined": "2026-09-05T12:57:28.125214+05:00" }, { "id": 6, "username": "testcashier", "email": "testcashier@example.com", "first_name": "Test", "last_name": "Cashier", "role": "CASHIER", "branch": 1, "branch_name": "Main Pharmacy", "phone": "03001234567", "cnic": "00000-0000000-0", "is_active_staff": true, "date_joined": "2026-09-05T13:25:59.489448+05:00" }, { "id": 7, "username": "cashier2", "email": "cashier2@example.com", "first_name": "Demo", "last_name": "Cashier", "role": "CASHIER", "branch": 1, "branch_name": "Main Pharmacy", "phone": "03001234567", "cnic": "00000-0000000-0", "is_active_staff": true, "date_joined": "2026-09-11T15:02:02.963509+05:00" } ] } | L19: Pass | N19: Abdullah | O19: 25th September 2026
A20: AUTH-16 | B20: Auth | C20: /api/auth/staff/ | D20: GET | E20: Cashier tries to list staff | F20: Cashier | G20: None | H20: (no body) | I20: 403 | J20: Permission denied — only Owner/Manager can view staff list | K20: { "success": false, "errors": { "detail": "Only owner or branch manager can perform this action." }, "status_code": 403 } | L20: Pass | N20: Abdullah | O20: 26th September 2026
A21: AUTH-17 | B21: Auth | C21: /api/auth/staff/ | D21: POST | E21: Owner creates a new Cashier for a specific branch | F21: Owner | G21: Branch already exists | H21: {"username":"cashier2","password":"Cashier2@123","role":"CASHIER","branch":1,"first_name":"Ahmed","last_name":"Khan"} | I21: 201 | J21: New user created, is_active_staff=true, role=CASHIER, branch=1 | K21: { "id": 7, "username": "cashier2", "email": "cashier2@example.com", "first_name": "Demo", "last_name": "Cashier", "role": "CASHIER", "branch": 1, "phone": "03001234567", "cnic": "00000-0000000-0" } | L21: Pass | N21: Abdullah | O21: 27th September 2026
A22: AUTH-18 | B22: Auth | C22: /api/auth/staff/ | D22: POST | E22: Manager creates staff — branch auto-assigned to manager's own branch even if a different branch id is sent | F22: Manager | G22: None | H22: {"username":"pharm2","password":"Pharm2@123","role":"PHARMACIST","branch":99} | I22: 201 | J22: User created with branch = manager's own branch (branch=99 ignored/overridden) | K22: { "id": 9, "username": "cashier3", "email": "cashier3@example.com", "first_name": "Demo", "last_name": "Cashier3", "role": "CASHIER", "branch": 1, "phone": "03001234567", "cnic": "00000-0000000-0" } | L22: Pass | N22: Abdullah | O22: 28th September 2026
A23: AUTH-19 | B23: Auth | C23: /api/auth/staff/ | D23: POST | E23: Attempt to create another OWNER via this endpoint | F23: Owner | G23: None | H23: {"username":"owner2","password":"Owner2@123","role":"OWNER"} | I23: 400 | J23: Validation error: 'Cannot create another OWNER account via this endpoint.' | K23: { "success": false, "errors": { "role": [ "Cannot create another OWNER account via this endpoint." ] }, "status_code": 400 } | L23: Pass | N23: Abdullah | O23: 29th September 2026
A24: AUTH-20 | B24: Auth | C24: /api/auth/staff/{id}/ | D24: PATCH | E24: Update a staff member's phone number | F24: Owner/Manager | G24: Staff id exists | H24: {"phone":"03001234567"} | I24: 200 | J24: Phone updated, other fields unchanged | K24: { "id": 2, "username": "manager1", "email": "", "first_name": "Sara", "last_name": "Manager", "role": "MANAGER", "branch": 1, "branch_name": "Main Pharmacy", "phone": "03001234567", "cnic": "", "is_active_staff": true, "date_joined": "2026-09-05T12:57:26.633080+05:00" } | L24: Pass | N24: Abdullah | O24: 30th September 2026
A25: AUTH-21 | B25: Auth | C25: /api/auth/staff/{id}/ | D25: DELETE | E25: Deactivate/remove a staff account | F25: Owner | G25: Staff id exists | H25: (no body) | I25: 204 | J25: Staff record deleted; that user can no longer log in | L25: Pass | N25: Abdullah | O25: 31st September 2026

Sheet Branches
A1: Pharmacy Chain ERP — API Test Plan: Branches
A2: Multi-branch chain management — opening/closing pharmacy locations. Owner-only write access.
A4: Test ID | B4: Module | C4: Endpoint | D4: Method | E4: Test Scenario | F4: Role / User | G4: Preconditions | H4: Sample Request Body | I4: Expected Status | J4: Expected Result | K4: Actual Result | L4: Status | M4: Bug / Notes | N4: Tested By | O4: Date Tested
A5: BR-01 | B5: Branches | C5: /api/branches/ | D5: GET | E5: Owner lists all branches | F5: Owner | G5: At least 2 branches exist | H5: (no body) | I5: 200 | J5: Returns every branch in the chain with staff_count | K5: { "count": 2, "next": null, "previous": null, "results": [ { "id": 1, "name": "Main Pharmacy", "code": "MAIN-01", "address": "Main Branch", "city": "Islamabad", "phone": "", "license_number": "", "is_active": true, "opened_on": null, "staff_count": 7, "created_at": "2026-09-05T12:57:24.309271+05:00", "updated_at": "2026-09-05T12:57:24.309271+05:00" }, { "id": 2, "name": "North Pharmacy", "code": "NORTH-01", "address": "North Market", "city": "Islamabad", "phone": "0511234567", "license_number": "LIC-NORTH-01", "is_active": true, "opened_on": "2026-09-05", "staff_count": 0, "created_at": "2026-09-05T13:27:25.778027+05:00", "updated_at": "2026-09-05T13:27:25.778027+05:00" } ] } | L5: Pass | N5: Abdullah | O5: 11th September 2026
A6: BR-02 | B6: Branches | C6: /api/branches/ | D6: GET | E6: Cashier lists branches — should only see own branch | F6: Cashier | G6: Multiple branches exist | H6: (no body) | I6: 200 | J6: Response contains exactly 1 branch: the cashier's own | K6: { "count": 1, "next": null, "previous": null, "results": [ { "id": 1, "name": "Main Pharmacy", "code": "MAIN-01", "address": "Main Branch", "city": "Islamabad", "phone": "0517654321", "license_number": "", "is_active": true, "opened_on": null, "staff_count": 7, "created_at": "2026-09-05T12:57:24.309271+05:00", "updated_at": "2026-09-11T15:21:51.758819+05:00" } ] } | L6: Pass
A7: BR-03 | B7: Branches | C7: /api/branches/ | D7: POST | E7: Owner opens a new branch | F7: Owner | G7: None | H7: {"name":"North Town Branch","code":"NTH-02","city":"Rawalpindi","address":"Main Blvd","phone":"0512345678"} | I7: 201 | J7: New branch created with is_active=true | K7: { "id": 3, "name": "North Town Branch", "code": "NTH-02", "address": "Main Blvd", "city": "Rawalpindi", "phone": "0512345678", "license_number": "", "is_active": true, "opened_on": null, "staff_count": 0, "created_at": "2026-09-11T15:18:55.275705+05:00", "updated_at": "2026-09-11T15:18:55.275705+05:00" } | L7: Pass
A8: BR-04 | B8: Branches | C8: /api/branches/ | D8: POST | E8: Non-owner (manager/cashier) tries to create a branch | F8: Manager | G8: None | H8: {"name":"Illegal Branch","code":"ILL-01"} | I8: 403 | J8: 'Only the owner can perform this action.' | K8: { "success": false, "errors": { "detail": "Only the owner can perform this action." }, "status_code": 403 } | L8: Pass
A9: BR-05 | B9: Branches | C9: /api/branches/ | D9: POST | E9: Create branch with duplicate code | F9: Owner | G9: A branch with code MAIN-01 already exists | H9: {"name":"Duplicate","code":"MAIN-01"} | I9: 400 | J9: Validation error: branch with this code already exists | K9: { "success": false, "errors": { "code": [ "branch with this code already exists." ] }, "status_code": 400 } | L9: Pass
A10: BR-06 | B10: Branches | C10: /api/branches/{id}/ | D10: GET | E10: Fetch single branch detail | F10: Owner/Manager | G10: Branch id exists | H10: (no body) | I10: 200 | J10: Full branch object returned | K10: { "id": 1, "name": "Main Pharmacy", "code": "MAIN-01", "address": "Main Branch", "city": "Islamabad", "phone": "", "license_number": "", "is_active": true, "opened_on": null, "staff_count": 7, "created_at": "2026-09-05T12:57:24.309271+05:00", "updated_at": "2026-09-05T12:57:24.309271+05:00" } | L10: Pass
A11: BR-07 | B11: Branches | C11: /api/branches/{id}/ | D11: PATCH | E11: Owner deactivates a branch (closing a location) | F11: Owner | G11: Branch id exists | H11: {"is_active":false} | I11: 200 | J11: is_active becomes false | K11: as expected | L11: Pass
A12: BR-08 | B12: Branches | C12: /api/branches/{id}/ | D12: DELETE | E12: Owner deletes a branch | F12: Owner | G12: Branch has no critical linked data (or test cascading behavior) | H12: (no body) | I12: 204 or 400 | J12: Deleted, OR blocked if protected FKs exist — verify which and document actual behavior | L12: Pass

Sheet Inventory
A1: Pharmacy Chain ERP — API Test Plan: Inventory
A2: Medicines catalog, batches (FEFO/expiry), stock movements, adjustments and inter-branch transfers.
A4: Test ID | B4: Module | C4: Endpoint | D4: Method | E4: Test Scenario | F4: Role / User | G4: Preconditions | H4: Sample Request Body | I4: Expected Status | J4: Expected Result | K4: Actual Result | L4: Status | M4: Bug / Notes | N4: Tested By | O4: Date Tested
A5: INV-01 | B5: Inventory | C5: /api/inventory/categories/ | D5: GET | E5: List medicine categories | F5: Any logged-in role | G5: At least 1 category exists | H5: (no body) | I5: 200 | J5: Array of categories returned | K5: { "count": 1, "next": null, "previous": null, "results": [ { "id": 1, "name": "Antibiotics", "description": "Updated category description" } ] } | L5: Pass
A6: INV-02 | B6: Inventory | C6: /api/inventory/categories/ | D6: POST | E6: Pharmacist creates a new category | F6: Pharmacist | G6: None | H6: {"name":"Antibiotics","description":"Antibiotic medicines"} | I6: 201 | J6: Category created | K6: { "id": 2, "name": "Antioxidants", "description": "Antioxidants medicines" } | L6: Pass
A7: INV-03 | B7: Inventory | C7: /api/inventory/categories/ | D7: POST | E7: Cashier tries to create a category (should be denied) | F7: Cashier | G7: None | H7: {"name":"Should Fail"} | I7: 403 | J7: Permission denied — only pharmacist/manager/owner can manage categories | K7: same as expected | L7: Pass
A8: INV-04 | B8: Inventory | C8: /api/inventory/manufacturers/ | D8: POST | E8: Create a manufacturer | F8: Pharmacist | G8: None | H8: {"name":"GSK Pakistan","country":"Pakistan"} | I8: 201 | J8: Manufacturer created | K8: { "id": 2, "name": "GSK Pakistan", "country": "Pakistan" } | L8: Pass
A9: INV-05 | B9: Inventory | C9: /api/inventory/medicines/ | D9: GET | E9: Search medicines by name/generic/sku | F9: Any | G9: Medicine 'Paracetamol 500mg' exists | H9: ?search=paracetamol | I9: 200 | J9: Returns matching medicines only | K9: { "count": 1, "next": null, "previous": null, "results": [ { "id": 1, "name": "Paracetamol 500mg", "generic_name": "Paracetamol", "sku": "PCM-500-DEMO", "barcode": "890000000001", "category": 1, "category_name": "Antibiotics", "manufacturer": 1, "manufacturer_name": "Demo Pharma", "unit_type": "TABLET", "pack_size": "10 tablets/strip", "requires_prescription": false, "is_active": true, "reorder_level": 10, "total_stock": 119, "created_at": "2026-09-05T13:29:06.217493+05:00", "updated_at": "2026-09-05T13:29:06.217493+05:00" } ] } | L9: Pass
A10: INV-06 | B10: Inventory | C10: /api/inventory/medicines/ | D10: GET | E10: Filter medicines by category & active status | F10: Any | G10: Categories assigned to medicines | H10: ?category=1&is_active=true | I10: 200 | J10: Only active medicines in category 1 returned | K10: { "count": 1, "next": null, "previous": null, "results": [ { "id": 1, "name": "Paracetamol 500mg", "generic_name": "Paracetamol", "sku": "PCM-500-DEMO", "barcode": "890000000001", "category": 1, "category_name": "Antibiotics", "manufacturer": 1, "manufacturer_name": "Demo Pharma", "unit_type": "TABLET", "pack_size": "10 tablets/strip", "requires_prescription": false, "is_active": true, "reorder_level": 10, "total_stock": 119, "created_at": "2026-09-05T13:29:06.217493+05:00", "updated_at": "2026-09-05T13:29:06.217493+05:00" } ] } | L10: Pass
A11: INV-07 | B11: Inventory | C11: /api/inventory/medicines/ | D11: POST | E11: Create a new medicine (master catalog entry) | F11: Pharmacist | G11: Category & manufacturer exist | H11: {"name":"Amoxicillin 500mg","sku":"AMX-500","category":1,"manufacturer":1,"unit_type":"CAPSULE","reorder_level":20,"requires_prescription":true} | I11: 201 | J11: Medicine created with is_active=true by default | K11: { "id": 2, "name": "Amoxicillin 500mg", "generic_name": "", "sku": "AMX-500", "barcode": "", "category": 1, "category_name": "Antibiotics", "manufacturer": 1, "manufacturer_name": "Demo Pharma", "unit_type": "CAPSULE", "pack_size": "", "requires_prescription": true, "is_active": true, "reorder_level": 20, "total_stock": 0, "created_at": "2026-09-11T15:59:03.204072+05:00", "updated_at": "2026-09-11T15:59:03.204072+05:00" } | L11: Pass
A12: INV-08 | B12: Inventory | C12: /api/inventory/medicines/ | D12: POST | E12: Create medicine with duplicate SKU | F12: Pharmacist | G12: SKU 'AMX-500' already exists | H12: {"name":"Duplicate","sku":"AMX-500"} | I12: 400 | J12: Validation error: sku must be unique | K12: { "success": false, "errors": { "sku": [ "medicine with this sku already exists." ] }, "status_code": 400 } | L12: Pass
A13: INV-09 | B13: Inventory | C13: /api/inventory/medicines/{id}/ | D13: GET | E13: Fetch medicine detail with branch-scoped total_stock | F13: Any | G13: Batches exist for this medicine | H13: ?branch=1 | I13: 200 | J13: total_stock reflects sum of quantity_remaining for branch 1 only | K13: { "id": 1, "name": "Paracetamol 500mg", "generic_name": "Paracetamol", "sku": "PCM-500-DEMO", "barcode": "890000000001", "category": 1, "category_name": "Antibiotics", "manufacturer": 1, "manufacturer_name": "Demo Pharma", "unit_type": "TABLET", "pack_size": "10 tablets/strip", "requires_prescription": false, "is_active": true, "reorder_level": 10, "total_stock": 119, "created_at": "2026-09-05T13:29:06.217493+05:00", "updated_at": "2026-09-05T13:29:06.217493+05:00" } | L13: Pass
A14: INV-10 | B14: Inventory | C14: /api/inventory/medicines/low_stock/ | D14: GET | E14: List medicines at/below reorder level for a branch | F14: Owner/Manager/Pharmacist | G14: At least one medicine's stock <= reorder_level | H14: ?branch=1 | I14: 200 | J14: Returns list with medicine_id, name, sku, total_stock, reorder_level | K14: [ { "medicine_id": 2, "name": "Amoxicillin 500mg", "sku": "AMX-500", "total_stock": 0, "reorder_level": 20 } ] | L14: Pass
A15: INV-11 | B15: Inventory | C15: /api/inventory/batches/ | D15: GET | E15: List batches filtered by branch/medicine, ordered by expiry | F15: Any | G15: Batches exist | H15: ?branch=1&medicine=1&ordering=expiry_date | I15: 200 | J15: Batches sorted soonest-expiry-first | K15: { "count": 2, "next": null, "previous": null, "results": [ { "id": 1, "medicine": 1, "medicine_name": "Paracetamol 500mg", "branch": 1, "branch_name": "Main Pharmacy", "batch_number": "DEMO-BATCH-001", "purchase_order_item": null, "quantity_received": 100, "quantity_remaining": 99, "cost_price": "10.00", "sale_price": "15.00", "expiry_date": "2027-12-31", "received_date": "2026-09-05", "is_active": true, "stock_value": "990.00", "is_expired": false, "is_near_expiry": false }, { "id": 2, "medicine": 1, "medicine_name": "Paracetamol 500mg", "branch": 1, "branch_name": "Main Pharmacy", "batch_number": "PO-DEMO-BATCH", "purchase_order_item": 1, "quantity_received": 20, "quantity_remaining": 20, "cost_price": "10.00", "sale_price": "15.00", "expiry_date": "2027-12-31", "received_date": "2026-09-05", "is_active": true, "stock_value": "200.00", "is_expired": false, "is_near_expiry": false } ] } | L15: Pass
A16: INV-12 | B16: Inventory | C16: /api/inventory/batches/ | D16: POST | E16: Manually create a batch (outside PO flow) | F16: Pharmacist | G16: Medicine & branch exist | H16: {"medicine":1,"branch":1,"batch_number":"MANUAL-001","quantity_received":50,"quantity_remaining":50,"cost_price":"8.00","sale_price":"12.00","expiry_date":"2027-06-30"} | I16: 201 | J16: Batch created and appears in stock totals | K16: { "id": 3, "medicine": 1, "medicine_name": "Paracetamol 500mg", "branch": 1, "branch_name": "Main Pharmacy", "batch_number": "MANUAL-001", "purchase_order_item": null, "quantity_received": 50, "quantity_remaining": 50, "cost_price": "8.00", "sale_price": "12.00", "expiry_date": "2027-06-30", "received_date": "2026-09-11", "is_active": true, "stock_value": "400.00", "is_expired": false, "is_near_expiry": false } | L16: Pass
... A23: INV-19 | B23: Inventory | C23: /api/inventory/stock-movements/ | D23: GET | E23: View full stock audit trail for a branch | F23: Any | G23: Movements exist (from POS sales, adjustments, transfers, PO receipts) | H23: ?branch=1&ordering=-created_at | I23: 200 | J23: Chronological list of every stock change with movement_type, quantity, reference | K23: { "count": 3, "next": null, "previous": null, "results": [ { "id": 4, "batch": 1, "medicine_name": "Paracetamol 500mg", "branch": 1, "branch_name": "Main Pharmacy", "movement_type": "TRANSFER_OUT", "quantity": -10, "reference": "TRANSFER-TO-NORTH-01", "note": "", "created_by": 5, "created_by_name": "Usman Pharmacist", "created_at": "2026-09-11T16:09:47.635544+05:00" }, { "id": 3, "batch": 1, "medicine_name": "Paracetamol 500mg", "branch": 1, "branch_name": "Main Pharmacy", "movement_type": "DAMAGED_WRITE_OFF", "quantity": -5, "reference": "", "note": "Water damage", "created_by": 5, "created_by_name": "Usman Pharmacist", "created_at": "2026-09-11T16:05:36.700618+05:00" }, { "id": 2, "batch": 1, "medicine_name": "Paracetamol 500mg", "branch": 1, "branch_name": "Main Pharmacy", "movement_type": "SALE_OUT", "quantity": -1, "reference": "MAIN-01-20260905125431-2899", "note": "", "created_by": 1, "created_by_name": "Ali Owner", "created_at": "2026-09-05T17:54:32.633419+05:00" } ] } | L23: Pass

Sheet Suppliers
A2: Suppliers, Purchase Orders, receiving stock into inventory, and manual supplier payment entries (accounts payable).
A4: Test ID | B4: Module | C4: Endpoint | D4: Method | E4: Test Scenario | F4: Role / User | G4: Preconditions | H4: Sample Request Body | I4: Expected Status | J4: Expected Result | K4: Actual Result | L4: Status | M4: Bug / Notes | N4: Tested By | O4: Date Tested
A5: SUP-01 | B5: Suppliers | C5: /api/suppliers/suppliers/ | D5: GET | E5: Search suppliers by name | F5: Any | G5: At least 1 supplier exists | H5: ?search=demo | I5: 200 | J5: Matching suppliers returned, each with total_payable computed | K5: { "count": 1, "next": null, "previous": null, "results": [ { "id": 1, "name": "Demo Distributors", "contact_person": "Ali Khan", "phone": "03003334444", "email": "sales@demo-distributors.example", "address": "Industrial Area", "is_active": true, "total_payable": 200.0, "created_at": "2026-09-05T13:32:20.271727+05:00" } ] } | L5: Pass
A6: SUP-02 | B6: Suppliers | C6: /api/suppliers/suppliers/ | D6: POST | E6: Create a new supplier | F6: Owner/Manager | G6: None | H6: {"name":"MediCorp Distributors","contact_person":"Bilal","phone":"03001112222"} | I6: 201 | J6: Supplier created | K6: { "id": 2, "name": "MediCorp Distributors", "contact_person": "Bilal", "phone": "03001112222", "email": "", "address": "", "is_active": true, "total_payable": 0, "created_at": "2026-09-11T16:26:01.700496+05:00" } | L6: Pass
A7: SUP-03 | B7: Suppliers | C7: /api/suppliers/suppliers/ | D7: POST | E7: Cashier tries to create a supplier (denied) | F7: Cashier | G7: None | H7: {"name":"Should Fail"} | I7: 403 | J7: Permission denied | K7: { "success": false, "errors": { "detail": "Only owner or branch manager can perform this action." }, "status_code": 403 } | L7: Pass
A8: SUP-04 | B8: Suppliers | C8: /api/suppliers/purchase-orders/ | D8: POST | E8: Create a Purchase Order with 2 line items (no branch field sent, non-owner) | F8: Manager | G8: Supplier & medicines exist | H8: {"supplier":1,"po_number":"PO-1001","items":[{"medicine":1,"quantity_ordered":100,"unit_cost":"8.00","unit_sale_price":"12.00","batch_number":"B-1001","expiry_date":"2027-05-01"},{"medicine":2,"quantity_ordered":50,"unit_cost":"5.00","unit_sale_price":"8.00"}]} | I8: 201 | J8: PO created with branch auto-assigned to manager's branch, status=DRAFT, 2 items nested | K8: { "success": false, "errors": { "branch": [ "This field is required." ] }, "status_code": 400 } | L8: Fail
A9: SUP-05 | B9: Suppliers | C9: /api/suppliers/purchase-orders/ | D9: POST | E9: Owner creates PO WITHOUT specifying branch (should now fail cleanly) | F9: Owner | G9: None | H9: {"supplier":1,"po_number":"PO-1002","items":[{"medicine":1,"quantity_ordered":10,"unit_cost":"8.00","unit_sale_price":"12.00"}]} | I9: 400 | J9: Clear validation error: 'Owner must specify a branch explicitly...' (NOT a 500 crash) | K9: { "success": false, "errors": { "branch": [ "This field is required." ] }, "status_code": 400 } | L9: Pass
A10: SUP-06 | B10: Suppliers | C10: /api/suppliers/purchase-orders/ | D10: POST | E10: Owner creates PO WITH branch specified | F10: Owner | G10: Branch id known | H10: {"branch":1,"supplier":1,"po_number":"PO-1003","items":[{"medicine":1,"quantity_ordered":10,"unit_cost":"8.00","unit_sale_price":"12.00"}]} | I10: 201 | J10: PO created for the specified branch | K10: { "id": 2, "branch": 1, "branch_name": "Main Pharmacy", "supplier": 1, "supplier_name": "Demo Distributors", "po_number": "PO-1003", "status": "DRAFT", "order_date": "2026-09-11", "expected_date": null, "received_date": null, "notes": "", "items": [ { "id": 2, "medicine": 1, "medicine_name": "Paracetamol 500mg", "quantity_ordered": 10, "quantity_received": 0, "unit_cost": "8.00", "unit_sale_price": "12.00", "batch_number": "", "expiry_date": null, "line_total": "80.00" } ], "total_amount": "80.00", "amount_paid": "0.00", "balance_due": "80.00", "created_at": "2026-09-11T16:28:48.470551+05:00" } | L10: Pass
A11: SUP-07 | B11: Suppliers | C11: /api/suppliers/purchase-orders/ | D11: GET | E11: List POs filtered by status | F11: Owner/Manager | G11: POs in different statuses exist | H11: ?branch=1&status=DRAFT&ordering=-created_at | I11: 200 | J11: Only DRAFT POs for branch 1 returned, with total_amount/amount_paid/balance_due computed | K11: { "count": 1, "next": null, "previous": null, "results": [ { "id": 2, "branch": 1, "branch_name": "Main Pharmacy", "supplier": 1, "supplier_name": "Demo Distributors", "po_number": "PO-1003", "status": "DRAFT", "order_date": "2026-09-11", "expected_date": null, "received_date": null, "notes": "", "items": [ { "id": 2, "medicine": 1, "medicine_name": "Paracetamol 500mg", "quantity_ordered": 10, "quantity_received": 0, "unit_cost": "8.00", "unit_sale_price": "12.00", "batch_number": "", "expiry_date": null, "line_total": "80.00" } ], "total_amount": "80.00", "amount_paid": "0.00", "balance_due": "80.00", "created_at": "2026-09-11T16:28:48.470551+05:00" } ] } | L11: Pass
A12: SUP-08 | B12: Suppliers | C12: /api/suppliers/purchase-orders/{id}/receive/ | D12: POST | E12: Fully receive a PO — verify inventory batches auto-created | F12: Owner/Manager | G12: PO in DRAFT/ORDERED status with items | H12: {} (receive all remaining items) | I12: 200 | J12: PO status becomes RECEIVED, received_date set; a Batch + StockMovement(PURCHASE_IN) created per item automatically | K12: { "detail": "0 batch(es) received into inventory.", "purchase_order": { "id": 1, "branch": 1, "branch_name": "Main Pharmacy", "supplier": 1, "supplier_name": "Demo Distributors", "po_number": "PO-DEMO-001", "status": "RECEIVED", "order_date": "2026-09-05", "expected_date": "2026-10-01", "received_date": "2026-09-11", "notes": "Approved for ordering", "items": [ { "id": 1, "medicine": 1, "medicine_name": "Paracetamol 500mg", "quantity_ordered": 20, "quantity_received": 20, "unit_cost": "10.00", "unit_sale_price": "15.00", "batch_number": "PO-DEMO-BATCH", "expiry_date": "2027-12-31", "line_total": "200.00" } ], "total_amount": "200.00", "amount_paid": "0.00", "balance_due": "200.00", "created_at": "2026-09-05T13:32:42.702090+05:00" } } | L12: Pass
A13: SUP-09 | B13: Suppliers | C13: /api/suppliers/purchase-orders/{id}/receive/ | D13: POST | E13: Partially receive only specific item_ids | F13: Owner/Manager | G13: PO has 2+ items | H13: {"item_ids":[3]} | I13: 200 | J13: Only item 3 marked received; PO status becomes PARTIALLY_RECEIVED | K13: { "detail": "0 batch(es) received into inventory.", "purchase_order": { "id": 1, "branch": 1, "branch_name": "Main Pharmacy", "supplier": 1, "supplier_name": "Demo Distributors", "po_number": "PO-DEMO-001", "status": "RECEIVED", "order_date": "2026-09-05", "expected_date": "2026-10-01", "received_date": "2026-09-11", "notes": "Approved for ordering", "items": [ { "id": 1, "medicine": 1, "medicine_name": "Paracetamol 500mg", "quantity_ordered": 20, "quantity_received": 20, "unit_cost": "10.00", "unit_sale_price": "15.00", "batch_number": "PO-DEMO-BATCH", "expiry_date": "2027-12-31", "line_total": "200.00" } ], "total_amount": "200.00", "amount_paid": "0.00", "balance_due": "200.00", "created_at": "2026-09-05T13:32:42.702090+05:00" } } | L13: Pass
A14: SUP-10 | B14: Suppliers | C14: /api/suppliers/purchase-orders/{id}/receive/ | D14: POST | E14: Re-receive an already fully-received PO | F14: Owner/Manager | G14: PO already RECEIVED | H14: {} | I14: 200 | J14: No duplicate batches created (quantity_received already == quantity_ordered), 0 batches returned | K14: { "detail": "0 batch(es) received into inventory.", "purchase_order": { "id": 1, "branch": 1, "branch_name": "Main Pharmacy", "supplier": 1, "supplier_name": "Demo Distributors", "po_number": "PO-DEMO-001", "status": "RECEIVED", "order_date": "2026-09-05", "expected_date": "2026-10-01", "received_date": "2026-09-11", "notes": "Approved for ordering", "items": [ { "id": 1, "medicine": 1, "medicine_name": "Paracetamol 500mg", "quantity_ordered": 20, "quantity_received": 20, "unit_cost": "10.00", "unit_sale_price": "15.00", "batch_number": "PO-DEMO-BATCH", "expiry_date": "2027-12-31", "line_total": "200.00" } ], "total_amount": "200.00", "amount_paid": "0.00", "balance_due": "200.00", "created_at": "2026-09-05T13:32:42.702090+05:00" } } | L14: Pass
A15: SUP-11 | B15: Suppliers | C15: /api/suppliers/payments/ | D15: POST | E15: Record a payment to a supplier (manual entry, no branch sent, as manager) | F15: Manager | G15: Supplier & PO exist | H15: {"supplier":1,"purchase_order":1,"bank_account":1,"amount":"500.00","method":"BANK_TRANSFER","reference_number":"TRX-9001"} | I15: 201 | J15: Payment recorded; branch auto-set to manager's branch | K15: { "success": false, "errors": { "detail": "Only owner or accountant can perform this action." }, "status_code": 403 } | L15: Fail
A16: SUP-12 | B16: Suppliers | C16: /api/suppliers/payments/ | D16: POST | E16: Owner records a cash payment to supplier without specifying branch | F16: Owner | G16: None | H16: {"supplier":1,"amount":"200.00","method":"CASH"} | I16: 400 | J16: Clear validation error requiring branch for owner (not a crash) | K16: { "success": false, "errors": { "branch": [ "This field is required." ] }, "status_code": 400 } | L16: Pass
... A18: SUP-14 | B18: Suppliers | C18: /api/suppliers/payments/ | D18: POST | E18: Cashier attempts to record a supplier payment (denied) | F18: Cashier | G18: None | H18: {"supplier":1,"amount":"100.00","method":"CASH"} | I18: 403 | J18: Permission denied — only owner/accountant can record supplier payments | K18: { "success": false, "errors": { "detail": "Only owner or accountant can perform this action." }, "status_code": 403 } | L18: Pass

Sheet Sales-POS
A1: Pharmacy Chain ERP — API Test Plan: Sales-POS
A2: Point-of-sale checkout, multi-payment split, returns, and invoice history. Core revenue-generating flow.
A4: Test ID | B4: Module | C4: Endpoint | D4: Method | E4: Test Scenario | F4: Role / User | G4: Preconditions | H4: Sample Request Body | I4: Expected Status | J4: Expected Result | K4: Actual Result | L4: Status | M4: Bug / Notes | N4: Tested By | O4: Date Tested
A5: POS-01 | B5: Sales-POS | C5: /api/sales/checkout/ | D5: POST | E5: Cashier completes a simple 1-item cash sale | F5: Cashier | G5: Batch has stock >= quantity, sale_price known | H5: {"customer":null,"items":[{"medicine_id":1,"quantity":1,"batch_id":1}],"payments":[{"method":"CASH","amount":"15.00"}]} | I5: 201 | J5: Invoice created, total_amount=15.00, batch.quantity_remaining reduced by 1, StockMovement(SALE_OUT) logged | K5: { "id": 2, "branch": 1, "branch_name": "Main Pharmacy", "invoice_number": "MAIN-01-20260911115416-1B70", "customer": null, "customer_name": null, "cashier": 3, "cashier_name": "Bilal Cashier", "subtotal": "15.00", "discount_amount": "0.00", "tax_amount": "0.00", "total_amount": "15.00", "status": "COMPLETED", "note": "", "items": [ { "id": 2, "batch": 1, "medicine_name_snapshot": "Paracetamol 500mg", "quantity": 1, "unit_price": "15.00", "unit_cost_snapshot": "10.00", "discount_amount": "0.00", "line_total": "15.00", "quantity_returned": 0, "profit": "5.00" } ], "payments": [ { "id": 2, "method": "CASH", "amount": "15.00", "bank_account": null, "reference_number": "" } ], "created_at": "2026-09-11T16:54:16.052366+05:00" } | L5: Pass
A6: POS-02 | B6: Sales-POS | C6: /api/sales/checkout/ | D6: POST | E6: Owner completes a sale — must specify branch explicitly | F6: Owner | G6: Owner has no home branch | H6: {"branch":1,"items":[{"medicine_id":1,"quantity":1}],"payments":[{"method":"CASH","amount":"15.00"}]} | I6: 201 | J6: Sale created for branch 1 with owner as cashier | K6: { "id": 14, "branch": 1, "branch_name": "Main Pharmacy", "invoice_number": "MAIN-01-20260911123052-FE24", "customer": null, "customer_name": null, "cashier": 1, "cashier_name": "Ali Owner", "subtotal": "12.00", "discount_amount": "0.00", "tax_amount": "0.00", "total_amount": "12.00", "status": "COMPLETED", "note": "", "items": [ { "id": 11, "batch": 3, "medicine_name_snapshot": "Paracetamol 500mg", "quantity": 1, "unit_price": "12.00", "unit_cost_snapshot": "8.00", "discount_amount": "0.00", "line_total": "12.00", "quantity_returned": 0, "profit": "4.00" } ], "payments": [ { "id": 13, "method": "CASH", "amount": "12.00", "bank_account": null, "reference_number": "" } ], "created_at": "2026-09-11T17:30:52.001385+05:00" } | L6: Pass
A7: POS-03 | B7: Sales-POS | C7: /api/sales/checkout/ | D7: POST | E7: Owner completes a sale WITHOUT specifying branch (should fail cleanly) | F7: Owner | G7: None | H7: {"items":[{"medicine_id":1,"quantity":1}],"payments":[{"method":"CASH","amount":"15.00"}]} | I7: 400 | J7: 'Owner has no home branch — specify which branch...' (not a 500 error) | K7: { "success": false, "errors": { "branch": "Owner has no home branch — specify which branch this sale is for (e.g. \"branch\": 1 in the request body)." }, "status_code": 400 } | L7: Pass
A8: POS-04 | B8: Sales-POS | C8: /api/sales/checkout/ | D8: POST | E8: Multi-item cart with FEFO auto batch selection (no batch_id given) | F8: Cashier | G8: Medicine has 2+ batches with different expiry dates | H8: {"items":[{"medicine_id":1,"quantity":5}],"payments":[{"method":"CASH","amount":"75.00"}]} | I8: 201 | J8: Stock deducted from the soonest-expiring batch first; if it lacks enough quantity, spills into the next batch | K8: { "success": false, "errors": [ "Payment total (75.00) does not match sale total (60.00)." ], "status_code": 400 } | L8: Fail
A9: POS-05 | B9: Sales-POS | C9: /api/sales/checkout/ | D9: POST | E9: Split payment across CASH + BANK_TRANSFER | F9: Cashier | G9: Sale total known in advance | H9: {"items":[{"medicine_id":1,"quantity":2}],"payments":[{"method":"CASH","amount":"20.00"},{"method":"BANK_TRANSFER","amount":"10.00","bank_account":1}]} | I9: 201 | J9: Both SalePayment rows created; sum matches total_amount | K9: { "success": false, "errors": [ "Payment total (30.00) does not match sale total (24.00)." ], "status_code": 400 } | L9: Fail
A10: POS-06 | B10: Sales-POS | C10: /api/sales/checkout/ | D10: POST | E10: Payment total does NOT match sale total | F10: Cashier | G10: None | H10: {"items":[{"medicine_id":1,"quantity":1}],"payments":[{"method":"CASH","amount":"5.00"}]} | I10: 400 | J10: 'Payment total (5.00) does not match sale total (15.00).' — sale is rolled back entirely (atomic transaction) | K10: { "success": false, "errors": [ "Payment total (5.00) does not match sale total (12.00)." ], "status_code": 400 } | L10: Pass
A11: POS-07 | B11: Sales-POS | C11: /api/sales/checkout/ | D11: POST | E11: Request more quantity than available stock | F11: Cashier | G11: Requested quantity > total available across all batches | H11: {"items":[{"medicine_id":1,"quantity":999999}],"payments":[{"method":"CASH","amount":"1.00"}]} | I11: 400 | J11: 'Insufficient stock for medicine id=1...' | K11: { "success": false, "errors": [ "Insufficient stock for medicine id=1. Requested 999999, available 151." ], "status_code": 400 } | L11: Pass
A12: POS-08 | B12: Sales-POS | C12: /api/sales/checkout/ | D12: POST | E12: Request a medicine with zero batches at this branch | F12: Cashier | G12: Medicine exists but has no batch at cashier's branch | H12: {"items":[{"medicine_id":<medicine_with_no_stock>,"quantity":1}],"payments":[{"method":"CASH","amount":"1.00"}]} | I12: 400 | J12: 'No available stock for medicine id=...' | K12: { "success": false, "errors": [ "No available stock for medicine id=12 at this branch." ], "status_code": 400 } | L12: Pass
A13: POS-09 | B13: Sales-POS | C13: /api/sales/checkout/ | D13: POST | E13: Empty cart submitted | F13: Cashier | G13: None | H13: {"items":[],"payments":[{"method":"CASH","amount":"0"}]} | I13: 400 | J13: 'Cart cannot be empty.' | K13: { "success": false, "errors": { "non_field_errors": [ "Cart cannot be empty." ] }, "status_code": 400 } | L13: Pass
A14: POS-10 | B14: Sales-POS | C14: /api/sales/checkout/ | D14: POST | E14: Attach an existing customer to the sale (loyalty context) | F14: Cashier | G14: Customer exists | H14: {"customer":1,"items":[{"medicine_id":1,"quantity":1}],"payments":[{"method":"CASH","amount":"15.00"}]} | I14: 201 | J14: Sale linked to customer_id=1 | K14: { "id": 12, "branch": 1, "branch_name": "Main Pharmacy", "invoice_number": "MAIN-01-20260911122623-9C00", "customer": 1, "customer_name": "Demo Customer", "cashier": 3, "cashier_name": "Bilal Cashier", "subtotal": "12.00", "discount_amount": "0.00", "tax_amount": "0.00", "total_amount": "12.00", "status": "COMPLETED", "note": "", "items": [ { "id": 9, "batch": 3, "medicine_name_snapshot": "Paracetamol 500mg", "quantity": 1, "unit_price": "12.00", "unit_cost_snapshot": "8.00", "discount_amount": "0.00", "line_total": "12.00", "quantity_returned": 0, "profit": "4.00" } ], "payments": [ { "id": 11, "method": "CASH", "amount": "12.00", "bank_account": null, "reference_number": "" } ], "created_at": "2026-09-11T17:26:23.838092+05:00" } | L14: Pass
A15: POS-11 | B15: Sales-POS | C15: /api/sales/returns/ | D15: POST | E15: Return part of a sold item's quantity | F15: Cashier | G15: A completed sale/sale_item exists with quantity>quantity_returned | H15: {"sale_item":1,"quantity":1,"reason":"Customer changed mind"} | I15: 201 | J15: quantity_returned incremented, batch.quantity_remaining restored, sale.status becomes PARTIALLY_RETURNED or RETURNED, refund_amount calculated | K15: { "detail": "Return processed.", "refund_amount": 15.0, "sale": { "id": 1, "branch": 1, "branch_name": "Main Pharmacy", "invoice_number": "MAIN-01-20260905125431-2899", "customer": null, "customer_name": null, "cashier": 1, "cashier_name": "Ali Owner", "subtotal": "15.00", "discount_amount": "0.00", "tax_amount": "0.00", "total_amount": "15.00", "status": "RETURNED", "note": "Demo POS checkout", "items": [ { "id": 1, "batch": 1, "medicine_name_snapshot": "Paracetamol 500mg", "quantity": 1, "unit_price": "15.00", "unit_cost_snapshot": "10.00", "discount_amount": "0.00", "line_total": "15.00", "quantity_returned": 1, "profit": "0.00" } ], "payments": [ { "id": 1, "method": "CASH", "amount": "15.00", "bank_account": null, "reference_number": "" } ], "created_at": "2026-09-05T17:54:31.698041+05:00" } } | L15: Pass
A16: POS-12 | B16: Sales-POS | C16: /api/sales/returns/ | D16: POST | E16: Attempt to return more than the remaining returnable quantity | F16: Cashier | G16: sale_item already fully returned or over-request | H16: {"sale_item":1,"quantity":9999} | I16: 400 | J16: 'Cannot return more than N remaining units.' | K16: { "success": false, "errors": [ "Cannot return more than 0 remaining units." ], "status_code": 400 } | L16: Pass
... A18: POS-14 | B18: Sales-POS | C18: /api/sales/invoices/{id}/ | D18: GET | E18: View full invoice detail (items + payments) | F18: Any (branch-scoped) | G18: Invoice id exists | H18: (no body) | I18: 200 | J18: Returns items array, payments array, computed profit per item | K18: { "id": 1, "branch": 1, "branch_name": "Main Pharmacy", "invoice_number": "MAIN-01-20260905125431-2899", "customer": null, "customer_name": null, "cashier": 1, "cashier_name": "Ali Owner", "subtotal": "15.00", "discount_amount": "0.00", "tax_amount": "0.00", "total_amount": "15.00", "status": "RETURNED", "note": "Demo POS checkout", "items": [ { "id": 1, "batch": 1, "medicine_name_snapshot": "Paracetamol 500mg", "quantity": 1, "unit_price": "15.00", "unit_cost_snapshot": "10.00", "discount_amount": "0.00", "line_total": "15.00", "quantity_returned": 1, "profit": "0.00" } ], "payments": [ { "id": 1, "method": "CASH", "amount": "15.00", "bank_account": null, "reference_number": "" } ], "created_at": "2026-09-05T17:54:31.698041+05:00" } | L18: Pass
A19: POS-15 | B19: Sales-POS | C19: /api/sales/invoices/ | D19: GET | E19: Cashier from Branch A tries to view Branch B's invoice by ID | F19: Cashier (Branch A) | G19: Invoice belongs to Branch B | H19: GET /api/sales/invoices/{branch_b_invoice_id}/ | I19: 404 | J19: Not found — branch scoping hides other branches' data entirely | L19: Pass

Sheet Finance
A1: Pharmacy Chain ERP — API Test Plan: Finance
A2: Manual bank account & transaction bookkeeping (no live bank API), daily cash register, and expense tracking.
A4: Test ID | B4: Module | C4: Endpoint | D4: Method | E4: Test Scenario | F4: Role / User | G4: Preconditions | H4: Sample Request Body | I4: Expected Status | J4: Expected Result | K4: Actual Result | L4: Status | M4: Bug / Notes | N4: Tested By | O4: Date Tested
A5: FIN-01 | B5: Finance | C5: /api/finance/bank-accounts/ | D5: POST | E5: Owner adds a head-office bank account (manual entry) | F5: Owner | G5: None | H5: {"bank_name":"HBL","account_title":"Pharmacy Chain Head Office","account_number":"01234567890123","branch":null} | I5: 201 | J5: Bank account created with current_balance=0.00 (manual bookkeeping, no real bank API) | K5: { "id": 2, "branch": null, "branch_name": "Head Office", "bank_name": "HBL", "account_title": "Pharmacy Chain Head Office", "account_number": "01234567890123", "iban": "", "current_balance": "0.00", "is_active": true, "created_at": "2026-09-11T19:17:52.950722+05:00" } | L5: Pass
A6: FIN-02 | B6: Finance | C6: /api/finance/bank-accounts/ | D6: POST | E6: Owner adds a branch-specific bank account | F6: Owner | G6: Branch exists | H6: {"bank_name":"Meezan Bank","account_title":"Main Pharmacy","account_number":"9988776655","branch":1} | I6: 201 | J6: Account created and tied to branch 1 | K6: { "id": 3, "branch": 1, "branch_name": "Main Pharmacy", "bank_name": "Meezan Bank", "account_title": "Main Pharmacy", "account_number": "9988776655", "iban": "", "current_balance": "0.00", "is_active": true, "created_at": "2026-09-11T19:18:24.459955+05:00" } | L6: Pass
A7: FIN-03 | B7: Finance | C7: /api/finance/bank-accounts/ | D7: GET | E7: Cashier/manager views bank accounts — scoped correctly | F7: Manager | G7: Both HQ and branch accounts exist | H7: (no body) | I7: 200 | J7: Sees accounts for own branch (and NOT other branches' accounts) | K7: { "id": 1, "branch": 1, "branch_name": "Main Pharmacy", "bank_name": "Demo Bank", "account_title": "Main Pharmacy Account", "account_number": "DEMO-ACC-001", "iban": "PK00DEMO0000000000000001", "current_balance": "0.00", "is_active": true, "created_at": "2026-09-05T13:34:46.469091+05:00" } | L7: Pass
A8: FIN-04 | B8: Finance | C8: /api/finance/bank-transactions/ | D8: POST | E8: Record a manual cash deposit from branch into bank | F8: Manager/Accountant | G8: Bank account exists | H8: {"bank_account":1,"branch":1,"tx_type":"DEPOSIT","amount":"5000.00","reference_number":"DEP-001","note":"End of day cash deposit"} | I8: 201 | J8: Transaction created; bank_account.current_balance increases by 5000.00 automatically | K8: { "id": 1, "bank_account": 1, "bank_name": "Demo Bank", "branch": 1, "branch_name": "Main Pharmacy", "tx_type": "DEPOSIT", "amount": "5000.00", "reference_number": "DEP-001", "note": "End of day cash deposit", "is_inflow": true, "created_by": 4, "created_at": "2026-09-11T19:21:28.647674+05:00" } | L8: Pass
A9: FIN-05 | B9: Finance | C9: /api/finance/bank-transactions/ | D9: POST | E9: Record a supplier payment transaction (money out) | F9: Accountant | G9: Bank account has sufficient recorded balance | H9: {"bank_account":1,"tx_type":"SUPPLIER_PAYMENT","amount":"1200.00","reference_number":"PAY-777"} | I9: 201 | J9: current_balance decreases by 1200.00 | K9: { "id": 2, "bank_account": 1, "bank_name": "Demo Bank", "branch": null, "branch_name": null, "tx_type": "SUPPLIER_PAYMENT", "amount": "1200.00", "reference_number": "PAY-777", "note": "", "is_inflow": false, "created_by": 4, "created_at": "2026-09-11T19:22:01.778240+05:00" } | L9: Pass
A10: FIN-06 | B10: Finance | C10: /api/finance/bank-transactions/ | D10: GET | E10: View full bank transaction ledger for a branch/date range | F10: Owner/Accountant | G10: Multiple transactions logged | H10: ?branch=1&tx_type=DEPOSIT | I10: 200 | J10: Filtered ledger with is_inflow computed per row | K10: { "count": 1, "next": null, "previous": null, "results": [ { "id": 1, "bank_account": 1, "bank_name": "Demo Bank", "branch": 1, "branch_name": "Main Pharmacy", "tx_type": "DEPOSIT", "amount": "5000.00", "reference_number": "DEP-001", "note": "End of day cash deposit", "is_inflow": true, "created_by": 4, "created_at": "2026-09-11T19:21:28.647674+05:00" } ] } | L10: Pass
A11: FIN-07 | B11: Finance | C11: /api/finance/cash-registers/ | D11: POST | E11: Cashier opens their daily cash drawer | F11: Cashier | G11: No OPEN register already exists for today | H11: {"opening_balance":"2000.00"} | I11: 201 | J11: Register created with status=OPEN, opened_by=self, branch auto-assigned | K11: { "success": false, "errors": { "branch": [ "This field is required." ] }, "status_code": 400 } | L11: Fail
A12: FIN-08 | B12: Finance | C12: /api/finance/cash-registers/{id}/close/ | D12: POST | E12: Cashier closes the register at end of day, entering counted cash | F12: Cashier | G12: Register is currently OPEN | H12: {"counted_closing_balance":"14850.00"} | I12: 200 | J12: status=CLOSED, closed_at set, variance = counted - expected computed (may show shortage/overage) | K12: { "success": false, "errors": { "detail": "No CashRegister matches the given query." }, "status_code": 404 } | L12: Pass
A13: FIN-09 | B13: Finance | C13: /api/finance/expense-categories/ | D13: POST | E13: Accountant adds a new expense category | F13: Accountant | G13: None | H13: {"name":"Electricity"} | I13: 201 | J13: Category created | K13: { "id": 6, "name": "Electricity" } | L13: Pass
A14: FIN-10 | B14: Finance | C14: /api/finance/expenses/ | D14: POST | E14: Record a rent expense paid from cash, no branch sent (manager) | F14: Manager | G14: Expense category exists | H14: {"category":1,"amount":"25000.00","paid_from":"CASH","description":"Monthly shop rent"} | I14: 201 | J14: Expense recorded, branch auto-assigned to manager's branch | K14: { "success": false, "errors": { "detail": "Only owner or accountant can perform this action." }, "status_code": 403 } | L14: Fail
A15: FIN-11 | B15: Finance | C15: /api/finance/expenses/ | D15: POST | E15: Record an expense paid from a specific bank account | F15: Accountant | G15: Bank account exists | H15: {"branch":1,"category":2,"amount":"6000.00","paid_from":"BANK","bank_account":1,"description":"Electricity bill"} | I15: 201 | J15: Expense linked to the bank account | K15: { "id": 1, "branch": 1, "branch_name": "Main Pharmacy", "category": 2, "category_name": "Utilities", "amount": "6000.00", "paid_from": "BANK", "bank_account": 1, "description": "Electricity bill", "expense_date": "2026-09-11", "created_by": 4, "created_at": "2026-09-11T19:28:53.922046+05:00" } | L15: Pass
A16: FIN-12 | B16: Finance | C16: /api/finance/expenses/ | D16: GET | E16: List expenses filtered by category & branch | F16: Owner/Accountant | G16: Expenses across categories exist | H16: ?branch=1&category=1 | I16: 200 | J16: Only matching expenses returned | K16: { "count": 0, "next": null, "previous": null, "results": [] } | L16: Fail

Sheet CRM
A1: Pharmacy Chain ERP — API Test Plan: CRM
A2: Customer records, loyalty points, and free-text CRM notes.
A4: Test ID | B4: Module | C4: Endpoint | D4: Method | E4: Test Scenario | F4: Role / User | G4: Preconditions | H4: Sample Request Body | I4: Expected Status | J4: Expected Result | K4: Actual Result | L4: Status | M4: Bug / Notes | N4: Tested By | O4: Date Tested
A5: CRM-01 | B5: CRM | C5: /api/crm/customers/ | D5: POST | E5: Cashier registers a new walk-in customer | F5: Cashier | G5: Phone number not already used | H5: {"name":"Fatima Noor","phone":"03211234567","email":""} | I5: 201 | J5: Customer created, home_branch auto-set to cashier's branch, loyalty_points=0 | K5: { "id": 2, "name": "Fatima Noor", "phone": "03211234567", "email": "", "address": "", "home_branch": 1, "home_branch_name": "Main Pharmacy", "loyalty_points": 0, "is_active": true, "lifetime_spend": "0.00", "created_at": "2026-09-11T19:01:31.053879+05:00" } | L5: Pass
